Workbook

Sheet Project Data
A1: Project Name | B1: Project 2 - NIM - Automated Thematic Analysis
A3: Online team meeting | B3: https://fau.zoom-x.de/j/64229233763?pwd=MboXckMTe5aVIBRIwvO71OgqjXJ7zb.1
A5: Production system (if any) | B5: ...
A6: Test system (if any) | B6: ...
A8: GitHub repository | B8: https://github.com/amosproj/amos2026ss02-automated-thematic-analysis
A9: GitHub feature board | B9: https://github.com/orgs/amosproj/projects/98
A10: GitHub imp-squared backlog | B10: https://github.com/orgs/amosproj/projects/102
A12: Position of T-shirt logo | B12: Upper Torso Right Small
A13: Link to logo for black T-shirt | B13: https://github.com/amosproj/amos2026ss02-automated-thematic-analysis/blob/main/Deliverables/sprint-01/team-logo.svg
A14: Link to logo for white T-shirt | B14: https://github.com/amosproj/amos2026ss02-automated-thematic-analysis/blob/main/Deliverables/sprint-01/team-logo.svg
A16: Additional materials | B16: ...
A18: Team mailing list | B18: oss-amos-proj2@lists.fau.de (Emails sent here get quarantined by the TU Berlin Spam Filter)

Sheet Project Team
A1: Last Name | B1: First Name | C1: GitHub User Name | D1: Email Address
A2: Kahvecioglu | B2: Selin | C2: slnkahveci | D2: kahvecioglu@campus.tu-berlin.de
A3: de Sa Filho | B3: Fabiano | C3: fdesafilho | D3: fabiano.de.sa@fau.de
A4: Ammann | B4: Paul | C4: Wecoreator | D4: p.ammann@campus.tu-berlin.de
A5: Schmidt | B5: Alexander | C5: alexanderschmi | D5: a.schmidt.2@tu-berlin.de
A6: Wendlandt | B6: Julian | C6: julianlucawendlandt-jpg | D6: julian.luca.wendlandt@campus.tu-berlin.de
A7: Müermann | B7: Ole | C7: ClimbTheGrind | D7: ole.mueermann@fau.de
A8: Klarer | B8: Paul | C8: paulKlarer | D8: paul.linus.klarer@fau.de
A9: Mantsch | B9: Christoph | C9: Christoph-Mantsch | D9: christoph.cm.mantsch@fau.de
A10: Annus | B10: Mohammad | C10: annus3 | D10: mohammad.annus@fau.de
A11: Rasul | B11: Hamid | C11: hrasul | D11: hamid.rasul@fau.de

Sheet Role Assignments
C1: Product Owner
A2: # | B2: Meeting Day | C2: Review | D2: Planning | E2: Software Developer | F2: Release Manager | G2: Scrum Master | H2: Comment
A3: 1 | B3: 46127 | C3: Alexander Schmidt | D3: Fabiano de Sa Filho | E3: Everyone else | F3: N/A | G3: Christoph Mantsch
A4: 2 | B4: =B3+7 -> 46134 | C4: Alexander Schmidt | D4: Fabiano de Sa Filho | E4: Everyone else | F4: Paul Klarer | G4: Christoph Mantsch
A5: 3 | B5: =B4+7 -> 46141 | C5: Fabiano de Sa Filho | D5: Alexander Schmidt | E5: Everyone else | F5: Paul Klarer | G5: Christoph Mantsch
A6: 4 | B6: =B5+7 -> 46148 | C6: Alexander Schmidt | D6: Fabiano de Sa Filho | E6: Everyone else | F6: Selin Kahvecioglu | G6: Christoph Mantsch
A7: 5 | B7: =B6+7 -> 46155 | C7: Fabiano de Sa Filho | D7: Alexander Schmidt | E7: Everyone else | F7: Ole Müermann | G7: Christoph Mantsch
A8: 6 | B8: =B7+7 -> 46162 | C8: Alexander Schmidt | D8: Fabiano de Sa Filho | E8: Everyone else | F8: Ole Müermann | G8: Christoph Mantsch
A9: 7 | B9: =B8+7 -> 46169 | C9: Fabiano de Sa Filho | D9: Alexander Schmidt | E9: Everyone else | F9: Hamid Rasul | G9: Christoph Mantsch | H9: Mid-term due
A10: 8 | B10: =B9+7 -> 46176 | C10: Alexander Schmidt | D10: Fabiano de Sa Filho | E10: Everyone else | F10: Selin Kahvecioglu | G10: Christoph Mantsch
A11: 9 | B11: =B10+7 -> 46183 | C11: Fabiano de Sa Filho | D11: Alexander Schmidt | E11: Everyone else | F11: Hamid Rasul | G11: Christoph Mantsch
A12: 10 | B12: =B11+7 -> 46190 | C12: Alexander Schmidt | D12: Fabiano de Sa Filho | E12: Everyone else | F12: Paul Ammann | G12: Christoph Mantsch
A13: 11 | B13: =B12+7 -> 46197 | C13: Fabiano de Sa Filho | D13: Alexander Schmidt | E13: Everyone else | F13: Mohammad Annus | G13: Christoph Mantsch
A14: 12 | B14: =B13+7 -> 46204 | C14: Alexander Schmidt | D14: Fabiano de Sa Filho | E14: Everyone else | F14: Mohammad Annus | G14: Christoph Mantsch
A15: 13 | B15: =B14+7 -> 46211 | C15: Fabiano de Sa Filho | D15: Alexander Schmidt | E15: Everyone else | F15: Paul Ammann | G15: Christoph Mantsch
A16: 14 | B16: =B15+7 -> 46218 | C16: Alexander Schmidt | D16: Fabiano de Sa Filho | E16: Everyone else | F16: Julian Wendlandt | G16: Christoph Mantsch | H16: Demo day!
A17: 15 | B17: =B16+7 -> 46225 | C17: Fabiano de Sa Filho | D17: Alexander Schmidt | E17: Everyone else | F17: Julian Wendlandt | G17: Christoph Mantsch | H17: Retrospective
A19: Product owners, software developers, and Scurm Master are set and ideally don't change over time; the critical part is the Release Manager role you need to define here

Sheet Team Contract
A1: Goals | B1: Having Fun
B2: Satisfy NIM
B3: Program an automated thematic analysis of interview transcripts
A4: Meeting norms | B4: Joining the meeting is mandatory
B5: Always be on time (up to 10 min late is fine if short message on discord)
B6: Follow the timeline
B7: Take notes in each meeting
B8: Happiness Index after Sprint retrospective
B9: Each meeting takes 1:30 hours
A10: Working norms | B10: Tell us if/when you are working on a task
B11: We encourage pair programming
A12: Coordination norms | B12: Self assign issues you are opening
B13: Do not force push
B14: Use PEP 8 as style (configure your IDEs)
B15: Follow https://www.atlassian.com/git/tutorials/comparing-workflows/gitflow-workflow
B16: Once every workday check discord
B17: If someone is blocked share with the team
A18: Communication norms | B18: Criticism should be productive
B19: Language should be respectful at all time (written and oral)
A20: Consideration norms | B20: Discuss disagreement openly
B21: Follow the NDA and data privacy
B22: Try not to induce bias in our project
A24: Cont. improvement norms | B24: Finish work until tuesday evening 20:00 PM
B25: At the end of the meeting discuss happyness score / what could be done better / what was good
A26: Rewards | B26: Have a happy meeting
A28: Sanctions | B28: Write a poem saying you are sorry
B29: After multiple or serious offenses escalate to prof
A30: Signatures
A32: Scrum Master | B32: Christoph Mantsch
A33: Product owner | B33: Alexander Schmidt
A34: Product owner | B34: Fabiano de Sa Filho
A35: Software developer | B35: Ole Müermann
A36: Software developer | B36: Julian Wendlandt
A37: Software developer | B37: Hamid Rasul
A38: Software developer | B38: Paul Klarer
A39: Software developer | B39: Paul Ammann
A40: Software developer | B40: Selin Kahvecioglu
A41: Software developer | B41: Mohammad Annus

Sheet Product Goal
A1: Product Vision | B1: Project Mission
A3: LLMs are a fantastic tool to interview research subjects at scale, which previously had to be done by human researchers. This method generates unstructured interview dialogues which must then be processed and analysed manually. The goal of this project is to use LLMs to also automate the analysis part, enabling policy researchers to feed their interview corpus to our tool and obtain not only the thematic analysis, but also relevant insights derived from the demographic data of the respondents. This way, we seek to bridge the gap between quantitative and qualitative policy research. | B3: To engineer a secure, open-source tool that ingests thousands of subject interviews about a policy topic and produces an accurate thematic analysis breakdown. The core is a multi-stage LLM pipeline that extracts quotes, codes them into themes, clusters and ranks those themes, and cross-references them against respondent demographic dimensions. Results are surfaced through a lightweight frontend and exportable in structured formats. We also provide direct reference back to the corpus, so researchers can see which interviews most strongly manifest a particular theme or demographic combination.

Sheet Product Glossary
A1: Term | B1: Definition
A2: Corpus / Dataset | B2: The LLM-led interviews on the economic impact of AI provided by the Industry Partner. Format: JSON
A3: Demographic Data | B3: Categorical variables describing each subject in the Corpus; has been partially sanitized by Industry partner, but must be handled with care. Absolutely should not be downloaded or uploaded to third parties. Format: CSV. Type: Numerical or Categorical Variables
A4: Thematic Analysis | B4: The qualitative method of identifying and analyzing patterns of meaning (themes) in a dataset. These themes should be followed by a short description and some quantitative measures of prevalence in the dataset.
A5: Analysis Run | B5: A single execution of the thematic analysis process based on a defined corpus, query, coding mode, and codebook. An analysis run produces outputs such as themes, tagged passages, and aggregated results.
A6: Codebook | B6: A structured collection of themes/codes used during thematic analysis. A codebook typically contains: - code/theme name - description - optional inclusion/exclusion criteria - optional examples
A7: Interview | B7: A textual dialogue between a research subject and an LLM about a research topic. It is provided by the industry partner in our case, and the interviews are about the Economic Impacts of AI in the job market.
A8: Demographic Data Variables | B8: Can be of two types: (1) Numerical: Continous variable like age, income. (2) Categorical: Classifies respondents into a category, such as gender, age bracket, level of schooling.
A9: Coding Mode | B9: The method by which the system determines and applies themes. The project currently includes three coding modes: - Fully automatic: The system consumes the corpus and produces the entire codebook without any human supervision, generating insights from the demographic data. - Semi-automatic: The system uses the corpus to produce a codebook, but allows the user to add, romove, and edit any of the themes. The system then procceds with the analyses using this edited codebook and receives natural language queries from the user, but does not modify the user-provided codebook in any way. - User-instructed: The system bypasses the codebook generation phase, and goes straight in to the natural language queries with the user provided codebook.
A10: Corpus View | B10: The product view that presents an aggregated overview of themes across the full corpus, including frequencies, quotes, and demographic breakdowns.
A11: Interview View | B11: The product view showing one full transcript, its highlighted themes, and the associated demographic information of the interviewee.
A12: Tag | B12: A thematic assignment attached to a specific passage in a transcript.
... A16: Code | B16: A short label, usually 5–12 words, that captures the central meaning of a quote or text chunk; it also has a description clarifying its scope.

Sheet Sprint Goals
A1: Sprint # | B1: Sprint goal
A2: 1 | B2: Meeting with industry partner, designing the logo, setting up the project
A3: =A2+1 -> 2 | B3: Ingesting the interview dataset provided by the industry partner, working on the Architecture Description document, and delivering a first prototype that successfully passes text through a basic LLM endpoint.
A4: =A3+1 -> 3 | B4: Creating a basic demo to be shown to Dr. Kaiser. Starting with simple views, database and llm communication
A5: =A4+1 -> 4 | B5: Creating the first version of the frontend, finishing up the basic demo of the backend. Adding a Readme and writting a proper Build script.
A6: =A5+1 -> 5 | B6: Closing up all features from previous sprints, finalizing the frontend so that we have a working demo for Industry Partner.
A7: =A6+1 -> 6 | B7: Working on the thematic analysis logic for the mid project release
A8: =A7+1 -> 7 | B8: Finishing work of Sprint 6. Refactoring and Optimization
A9: =A8+1 -> 8 | B9: Start on Apply codebook to Corpus
A10: =A9+1 -> 9 | B10: Finish Apply Codeboook to Corpus and other minor issues
A11: =A10+1 -> 10 | B11: Focus on displaying all of the transcripts for a particular theme and adding external API Support. Minor fixes requested by Dr.Kaiser
A12: =A11+1 -> 11 | B12: Finish Analysis Visualization, Integrate incremental Codebook Generation and Application
A13: =A12+1 -> 12
A14: =A13+1 -> 13
A15: =A14+1 -> 14
A16: =A15+1 -> 15

Sheet Velocity Tracking
A1: Sprint # | B1: Story Points Realized | C1: Story Points Planned | D1: Average Planned | E1: Average Realized
A2: 1 | B2: ='Final Project Release plan'!F9 -> 5 | C2: ='Final Project Release plan'!D9 -> 5 | D2: =AVERAGE(C2:C16) -> 15 | E2: =AVERAGE(B2:B16) -> 16.545455
A3: =A2+1 -> 2 | B3: ='Final Project Release plan'!F10 -> 39 | C3: ='Final Project Release plan'!D10 -> 19 | D3: =D2 -> 15 | E3: =E2 -> 16.545455
A4: =A3+1 -> 3 | B4: ='Final Project Release plan'!F11 -> 22 | C4: ='Final Project Release plan'!D11 -> 22 | D4: =D2 -> 15 | E4: =E2 -> 16.545455
A5: =A4+1 -> 4 | B5: ='Final Project Release plan'!F12 -> 13 | C5: ='Final Project Release plan'!D12 -> 10 | D5: =D2 -> 15 | E5: =E2 -> 16.545455
A6: =A5+1 -> 5 | B6: ='Final Project Release plan'!F13 -> 19 | C6: ='Final Project Release plan'!D13 -> 19 | D6: =D2 -> 15 | E6: =E2 -> 16.545455
A7: =A6+1 -> 6 | B7: ='Final Project Release plan'!F14 -> 5 | C7: ='Final Project Release plan'!D14 -> 5 | D7: =D2 -> 15 | E7: =E2 -> 16.545455
A8: =A7+1 -> 7 | B8: ='Final Project Release plan'!F15 -> 11 | C8: ='Final Project Release plan'!D15 -> 9 | D8: =D2 -> 15 | E8: =E2 -> 16.545455
A9: =A8+1 -> 8 | B9: ='Final Project Release plan'!F16 -> 10 | C9: ='Final Project Release plan'!D16 -> 12 | D9: =D2 -> 15 | E9: =E2 -> 16.545455
A10: =A9+1 -> 9 | B10: ='Final Project Release plan'!F17 -> 27 | C10: ='Final Project Release plan'!D17 -> 27 | D10: =D2 -> 15 | E10: =E2 -> 16.545455
A11: =A10+1 -> 10 | B11: ='Final Project Release plan'!F18 -> 22 | C11: ='Final Project Release plan'!D18 -> 28 | D11: =D2 -> 15 | E11: =E2 -> 16.545455
A12: =A11+1 -> 11 | B12: ='Final Project Release plan'!F19 -> 9 | C12: ='Final Project Release plan'!D19 -> 9 | D12: =D2 -> 15 | E12: =E2 -> 16.545455
A13: =A12+1 -> 12 | D13: =D2 -> 15 | E13: =E2 -> 16.545455
A14: =A13+1 -> 13 | D14: =D2 -> 15 | E14: =E2 -> 16.545455
A15: =A14+1 -> 14 | D15: =D2 -> 15 | E15: =E2 -> 16.545455
A16: =A15+1 -> 15 | D16: =D2 -> 15 | E16: =E2 -> 16.545455
B18: PLEASE CREATE THE VELOCITY CHART ON A NEW TAB USING THE DATA FROM THIS TAB

Sheet Mid-Project Release plan
A1: Sprint | B1: Goal | C1: Feature Name | D1: Est. size | E1: Est. remaining | F1: Real size | G1: Real remaining
A3: Release
A5: Total | D5: =sum(D9:D14) -> 89 | F5: =SUM(F8:F14) -> 98
A7: Sprints
A8: 0 | E8: Estimated burn-down | G8: Real burn-down
A9: 1 | B9: ='Sprint Goals'!B2 -> Meeting with industry partner, designing the logo, setting up the project | D9: =sum(D24:D29) -> 5 | E9: =$D$5-D9 -> 84 | F9: =sum(F24:F29) -> 5 | G9: =F5 -> 98
A10: =A9+1 -> 2 | B10: ='Sprint Goals'!B3 -> Ingesting the interview dataset provided by the industry partner, working on the Architecture Description document, and delivering a first prototype that successfully passes text through a basic LLM endpoint. | D10: =sum(D31:D33) -> 19 | E10: =E9-D10 -> 65 | F10: =sum(F31:F34) -> 39 | G10: =G9-F9 -> 93
A11: =A10+1 -> 3 | B11: ='Sprint Goals'!B4 -> Creating a basic demo to be shown to Dr. Kaiser. Starting with simple views, database and llm communication | D11: =sum(D36:D41) -> 22 | E11: =E10-D11 -> 43 | F11: =sum(F37:F41) -> 22 | G11: =G10-F10 -> 54
A12: 4 | B12: ='Sprint Goals'!B5 -> Creating the first version of the frontend, finishing up the basic demo of the backend. Adding a Readme and writting a proper Build script. | D12: =SUM(D44:D48) -> 10 | E12: =E11-D12 -> 33 | F12: =sum(F44:F48) -> 13 | G12: =G11-F11 -> 32
A13: =A12+1 -> 5 | B13: ='Sprint Goals'!B6 -> Closing up all features from previous sprints, finalizing the frontend so that we have a working demo for Industry Partner. | D13: =sum(D51:D54) -> 19 | E13: =E12-D13 -> 14 | F13: =sum(F51:F54) -> 19 | G13: =G12-F12 -> 19
A14: =A13+1 -> 6 | B14: ='Sprint Goals'!B7 -> Working on the thematic analysis logic for the mid project release | D14: =sum(D57:D61) -> 14 | E14: =E13-D14 -> 0 | F14: =sum(F57:F61) -> 0 | G14: =G13-F13 -> 0
A22: Features
A24: =A9 -> 1 | B24: =B9 -> Meeting with industry partner, designing the logo, setting up the project
C25: Designing Project Logo | D25: 5 | F25: 5
A30: =A10 -> 2 | B30: =B10 -> Ingesting the interview dataset provided by the industry partner, working on the Architecture Description document, and delivering a first prototype that successfully passes text through a basic LLM endpoint.
C31: Select Open source model for Generation Phase | D31: 3 | F31: 5
C32: Create PDF of software architecture description | D32: 8 | F32: 13
C33: Software Bill of Material | D33: 8 | F33: 13
C34: Setting up the Repo with FastAPI, docker, etc | D34: 8 | F34: 8
A36: =A11 -> 3 | B36: =B11 -> Creating a basic demo to be shown to Dr. Kaiser. Starting with simple views, database and llm communication
C37: Simple Data persistence Layer | D37: 5 | F37: 5
C38: View Theme Overview | D38: 8 | F38: 8
C39: Automated Database structure Setup | D39: 1 | F39: 1
C40: First LLM Request Setup | D40: 3 | F40: 3
C41: Plan Build Proccess | D41: 5 | F41: 5
A43: =A12 -> 4 | B43: =B12 -> Creating the first version of the frontend, finishing up the basic demo of the backend. Adding a Readme and writting a proper Build script.
C44: Upload Interview Transcript | D44: 3 | F44: 3
C45: Apply Codebook to interview | D45: 3 | F45: 3
C46: Add root README.md file | D46: 1 | F46: 1
C47: Implement Build Proccess | D47: 1 | F47: 3
C48: Setup Frontend for document Upload | D48: 2 | F48: 3
A50: =A13 -> 5 | B50: =B13 -> Closing up all features from previous sprints, finalizing the frontend so that we have a working demo for Industry Partner.
C51: Setup Frontend | D51: 8 | F51: 8
C52: Link Transcripts and Demographic Data | D52: 5 | F52: 3
C53: Upload Predefined Codebook | D53: 3 | F53: 3
C54: Upload Demographic Data | D54: 3 | F54: 5
A56: =A14 -> 6 | B56: =B14 -> Working on the thematic analysis logic for the mid project release
C57: Implement Automatic Codebook Generation | D57: 5
C58: Demographic Data Upload Frontend | D58: 2
C59: Demographic Data Viewer Page | D59: 2
...

Sheet Velocity Chart
B7: =average('Velocity Tracking'!B2:B12) -> 16.545455
B8: =B7 -> 16.545455
B9: =B8 -> 16.545455
B10: =B9 -> 16.545455
B11: =B10 -> 16.545455
B12: =B11 -> 16.545455
B13: =B12 -> 16.545455
B14: =B13 -> 16.545455
B15: =B14 -> 16.545455
B16: =B15 -> 16.545455
B17: =B16 -> 16.545455
B18: =B17 -> 16.545455
B19: =B18 -> 16.545455
A33: Scrum Master Charts

Sheet Burndown Chart
E6: ='Mid-Project Release plan'!D5 -> 89 | F6: =E6 -> 89
E7: =E6-C26 -> 74.166667 | F7: ='Mid-Project Release plan'!E9 -> 84
E8: =E7-C26 -> 59.333333 | F8: ='Mid-Project Release plan'!E10 -> 65
E9: =E8-C26 -> 44.5 | F9: ='Mid-Project Release plan'!E11 -> 43
E10: =E9-C26 -> 29.666667 | F10: ='Mid-Project Release plan'!E12 -> 33
E11: =E10-C26 -> 14.833333 | F11: ='Mid-Project Release plan'!E13 -> 14
E12: =E11-C26 -> 0 | F12: ='Mid-Project Release plan'!E14 -> 0
B26: Speed | C26: ='Mid-Project Release plan'!D5/'Mid-Project Release plan'!A14 -> 14.833333 | D26: sp

Sheet Final Project Release plan
A1: Sprint | B1: Goal | C1: Feature Name | D1: Est. size | E1: Est. remaining | F1: Real size | G1: Real remaining
A3: Release
A5: Total | D5: =sum(D9:D21) -> 165 | F5: =SUM(F8:F21) -> 182
A7: Sprints
A8: 0 | E8: =D5 -> 165 | G8: Real burn-down
A9: 1 | B9: ='Sprint Goals'!B2 -> Meeting with industry partner, designing the logo, setting up the project | D9: =sum(D24:D29) -> 5 | E9: =$D$5-D9 -> 160 | F9: =sum(F24:F29) -> 5 | G9: =F5-F9 -> 177
A10: =A9+1 -> 2 | B10: ='Sprint Goals'!B3 -> Ingesting the interview dataset provided by the industry partner, working on the Architecture Description document, and delivering a first prototype that successfully passes text through a basic LLM endpoint. | D10: =sum(D31:D33) -> 19 | E10: =E9-D10 -> 141 | F10: =sum(F31:F34) -> 39 | G10: =G9-F10 -> 138
A11: =A10+1 -> 3 | B11: ='Sprint Goals'!B4 -> Creating a basic demo to be shown to Dr. Kaiser. Starting with simple views, database and llm communication | D11: =sum(D36:D41) -> 22 | E11: =E10-D11 -> 119 | F11: =sum(F37:F41) -> 22 | G11: =G10-F11 -> 116
A12: 4 | B12: ='Sprint Goals'!B5 -> Creating the first version of the frontend, finishing up the basic demo of the backend. Adding a Readme and writting a proper Build script. | D12: =SUM(D44:D48) -> 10 | E12: =E11-D12 -> 109 | F12: =sum(F44:F48) -> 13 | G12: =G11-F12 -> 103
A13: =A12+1 -> 5 | B13: ='Sprint Goals'!B6 -> Closing up all features from previous sprints, finalizing the frontend so that we have a working demo for Industry Partner. | D13: =sum(D51:D54) -> 19 | E13: =E12-D13 -> 90 | F13: =sum(F51:F54) -> 19 | G13: =G12-F13 -> 84
A14: =A13+1 -> 6 | B14: ='Sprint Goals'!B7 -> Working on the thematic analysis logic for the mid project release | D14: =sum(D57) -> 5 | E14: =E13-D14 -> 85 | F14: =sum(F57) -> 5 | G14: =G13-F14 -> 79
A15: 7 | B15: ='Sprint Goals'!B8 -> Finishing work of Sprint 6. Refactoring and Optimization | D15: =sum(D60:D63) -> 9 | E15: =E14-D15 -> 76 | F15: =SUM(F60:F64) -> 11 | G15: =G14-F15 -> 68
A16: 8 | B16: ='Sprint Goals'!B9 -> Start on Apply codebook to Corpus | D16: =SUM(D67:D70) -> 12 | E16: =E15-D16 -> 64 | F16: =SUM(F67:F70) -> 10 | G16: =G15-F16 -> 58
A17: 9 | B17: ='Sprint Goals'!B10 -> Finish Apply Codeboook to Corpus and other minor issues | D17: =SUM(D73:D79) -> 27 | E17: =E16-D17 -> 37 | F17: =SUM(F73:F79) -> 27 | G17: =G16-F17 -> 31
A18: 10 | B18: ='Sprint Goals'!B11 -> Focus on displaying all of the transcripts for a particular theme and adding external API Support. Minor fixes requested by Dr.Kaiser | D18: =SUM(D82:D88) -> 28 | E18: =E17-D18 -> 9 | F18: =SUM(F82:F88) -> 22 | G18: =G17-F18 -> 9
A19: 11 | B19: ='Sprint Goals'!B12 -> Finish Analysis Visualization, Integrate incremental Codebook Generation and Application | D19: =SUM(D91:D95) -> 9 | E19: =E18-D19 -> 0 | F19: =SUM(F91:F95) -> 9 | G19: =G18-F19 -> 0
B20: ='Sprint Goals'!B13
B21: ='Sprint Goals'!B14
A22: Features
A24: =A9 -> 1 | B24: =B9 -> Meeting with industry partner, designing the logo, setting up the project
C25: Designing Project Logo | D25: 5 | F25: 5
A30: =A10 -> 2 | B30: =B10 -> Ingesting the interview dataset provided by the industry partner, working on the Architecture Description document, and delivering a first prototype that successfully passes text through a basic LLM endpoint.
C31: Select Open source model for Generation Phase | D31: 3 | F31: 5
C32: Create PDF of software architecture description | D32: 8 | F32: 13
C33: Software Bill of Material | D33: 8 | F33: 13
C34: Setting up the Repo with FastAPI, docker, etc | D34: 8 | F34: 8
A36: =A11 -> 3 | B36: =B11 -> Creating a basic demo to be shown to Dr. Kaiser. Starting with simple views, database and llm communication
C37: Simple Data persistence Layer | D37: 5 | F37: 5
C38: View Theme Overview | D38: 8 | F38: 8
C39: Automated Database structure Setup | D39: 1 | F39: 1
C40: First LLM Request Setup | D40: 3 | F40: 3
C41: Plan Build Proccess | D41: 5 | F41: 5
A43: =A12 -> 4 | B43: =B12 -> Creating the first version of the frontend, finishing up the basic demo of the backend. Adding a Readme and writting a proper Build script.
C44: Upload Interview Transcript | D44: 3 | F44: 3
C45: Apply Codebook to interview | D45: 3 | F45: 3
C46: Add root README.md file | D46: 1 | F46: 1
C47: Implement Build Proccess | D47: 1 | F47: 3
C48: Setup Frontend for document Upload | D48: 2 | F48: 3
A50: =A13 -> 5 | B50: =B13 -> Closing up all features from previous sprints, finalizing the frontend so that we have a working demo for Industry Partner.
C51: Setup Frontend | D51: 8 | F51: 8
...

Sheet Final Velocity Chart
C9: =average('Velocity Tracking'!B2:B14) -> 16.545455
C10: =C9 -> 16.545455
C11: =C10 -> 16.545455
C12: =C11 -> 16.545455
C13: =C12 -> 16.545455
C14: =C13 -> 16.545455
C15: =C14 -> 16.545455
C16: =C15 -> 16.545455
C17: =C16 -> 16.545455
C18: =C17 -> 16.545455
C19: =C18 -> 16.545455
C20: =C19 -> 16.545455
C21: =C20 -> 16.545455
A33: Scrum Master Charts

Sheet Final Burndown Chart
E7: ='Final Project Release plan'!D5 -> 165 | F7: =E7 -> 165
E8: =E7-C26 -> 148.5 | F8: ='Final Project Release plan'!E9 -> 160
E9: =E8-C26 -> 132 | F9: ='Final Project Release plan'!E10 -> 141
E10: =E9-C26 -> 115.5 | F10: ='Final Project Release plan'!E11 -> 119
E11: =E10-C26 -> 99 | F11: ='Final Project Release plan'!E12 -> 109
E12: =E11-C26 -> 82.5 | F12: ='Final Project Release plan'!E13 -> 90
E13: =E12-C26 -> 66 | F13: ='Final Project Release plan'!E14 -> 85
E14: =E13-C26 -> 49.5 | F14: ='Final Project Release plan'!E15 -> 76
E15: =E14-C26 -> 33 | F15: ='Final Project Release plan'!E16 -> 64
E16: =E15-C26 -> 16.5
E17: =E16-C26 -> 0
B26: Speed | C26: ='Final Project Release plan'!D5/'Final Project Release plan'!A18 -> 16.5 | D26: sp

Sheet Definition of Done
A1: # | B1: Feature Definition of Done | C1: Sprint Release Definition of Done | D1: Project Release Definition of Done
B2: New feature code has been documented, READMEs have been updated to reflect changes | C2: Project builds, deploys, and tests successfully | D2: Deployment process is tested and documented
B3: Unit tests for relevant logic are written and passing | C3: All stories committed as “done” meet the Feature Definition of Done | D3: User documentation has been updated
B4: Feature has been fully implemented | C4: All completed features are integrated into the main branch | D4: Architecture documentation and Bill of Materials is up to date
B5: Feature has been merged into the mainline | C5: Documentation and READMEs reflect changes made in the sprint | D5: The released product increment solves the intended user problem at a usable level
B6: All acceptance criteria were met | C6: Incomplete items are clearly identified and moved/replanned | D6: Performance is acceptable for the expected usage volume
B7: Product owner approved features | C7: Retrospective completed | D7: The user is able to install and use the application with minimal configuration
B8: Developers agreed to release | C8: All implemented features are moved to the feature archive and their issues marked as closed | D8: No critical or high bugs remain

Sheet Documentation
A1: Type | B1: Link / reference

Sheet Bill of Materials
A1: # | B1: Context | C1: Name | D1: Version | E1: License | F1: Comment
A2: 1 | B2: Database | C2: PostgreSQL | D2: 18 | E2: PostgreSQL License | F2: Reliable open-source relational database for structured application data.
A3: 2 | B3: Database extension | C3: pgvector | D3: 0.8 | E3: PostgreSQL License | F3: Adds vector storage and similarity search directly inside PostgreSQL
A4: 3 | B4: Programming language / runtime | C4: Python | D4: 3.11 | E4: Python Software Foundation License Version 2 | F4: Core runtime for backend
A5: 4 | B5: Database ORM / SQL toolkit | C5: SQLAlchemy | D5: 2 | E5: MIT | F5: Provides Python ORM and SQL toolkit support for database access and queries.
A6: 5 | B6: Backend API framework | C6: FastAPI | D6: 0.136 | E6: MIT | F6: Build easy python basd APIs
A7: 6 | B7: Data validation | C7: Pydantic | D7: 2.13 | E7: MIT | F7: Validates, parses, and serializes Python data models safely.
A8: 7 | B8: LLM application framework | C8: LangChain | D8: 1.2 | E8: MIT | F8: Build LLM workflows
A9: 8 | B9: NLP library | C9: spaCy | D9: 3.8 | E9: MIT | F9: Provides production-ready NLP features such as tokenization, NER, and pipelines. Contains e.g. BERT Implementations for NLP tasks like classification
A10: 9 | B10: ASGI server | C10: Uvicorn | D10: 0.46 | E10: BSD-3-Clause | F10: Runs the FastAPI backend
A11: 10 | B11: PostgreSQL async driver | C11: asyncpg | D11: 0.31 | E11: Apache License 2.0 | F11: Provides fast asynchronous PostgreSQL connectivity for Python services.
A12: 11 | B12: LLM observability | C12: Langfuse | D12: 4.5 | E12: MIT Expat for core; enterprise directories under separate ee/LICENSE | F12: Tracks LLM traces, prompts, latency, costs, and evaluation data.
A13: 12 | B13: HTTP client | C13: HTTPX | D13: 0.28 | E13: BSD-3-Clause | F13: Provides sync and async HTTP calls to model APIs and backend services.
... A17: 16 | B17: LLM frontend prototyping | C17: Streamlit | D17: 1.56 | E17: Apache License 2.0 | F17: Quickly builds Python-based web apps, dashboards, and chat prototypes for LLM applications. Used for protoyping & early previews.
A18: 17 | B18: Large language model | C18: Gemma | D18: Gemma 4 31B | E18: Apache License 2.0 | F18: Candidate self-hosted open model. More details in the model selection document. Final model decision is still outstanding.
A19: 18 | B19: Large language model | C19: Qwen | D19: Qwen3.5-35B-A3B | E19: Apache License 2.0 | F19: Candidate self-hosted open model. More details in the model selection document. Final model decision is still outstanding.
A20: 19 | B20: Large language model | C20: Mixtral | D20: Mixtral 8x7B | E20: Apache License 2.0 | F20: Candidate self-hosted open model. More details in the model selection document. Final model decision is still outstanding.
A21: 20 | B21: LLM gateway / provider abstraction | C21: LiteLLM | D21: 1.83 | E21: MIT for OSS package; enterprise package/features under separate commercial license | F21: Provides a unified OpenAI-compatible interface for calling multiple LLM providers.
A22: 21 | B22: Containerization / deployment | C22: Docker Engine | D22: 29 | E22: Apache License 2.0 | F22: Packages and runs the application stack consistently across environments.
A23: 22 | B23: Web framework | C23: Flask | D23: 3.1 | E23: BSD-3-Clause | F23: Server-side web framework for the production frontend
A24: 23 | B24: Template engine | C24: Jinja2 | D24: 3.1 | E24: BSD-3-Clause | F24: Template engine used with Flask to generate server-rendered HTML views
A25: 24 | B25: Chat / users | C25: OpenWebUI | D25: 0.9 | E25: Open WebUI License | F25: chat-style interaction and user management. Current OpenWebUI versions use the Open WebUI License, which is based on BSD-3-Clause but adds a branding / attribution restriction

Sheet Planning Poker
B1: ='Project Team'!B1 -> First Name | C1: Value
A2: ='Project Team'!A2 -> Kahvecioglu | B2: ='Project Team'!B2 -> Selin | C2: 2 | E2: =average(C2:C10) -> 2 | F2: =if(stdev(C2:C7) > 0,"NOK", "OK") -> OK
A3: ='Project Team'!A3 -> de Sa Filho | B3: ='Project Team'!B3 -> Fabiano | C3: N/A
A4: ='Project Team'!A4 -> Ammann | B4: ='Project Team'!B4 -> Paul | C4: 2
A6: ='Project Team'!A6 -> Wendlandt | B6: ='Project Team'!B6 -> Julian | C6: 2 | E6: 0 | F6: No size
A7: ='Project Team'!A7 -> Müermann | B7: ='Project Team'!B7 -> Ole | C7: 2 | E7: 1 | F7: Trivial size
A8: ='Project Team'!A8 -> Klarer | B8: ='Project Team'!B8 -> Paul | C8: 2 | E8: 2 | F8: Small size
E9: 3 | F9: Medium size
A10: ='Project Team'!A10 -> Annus | B10: ='Project Team'!B10 -> Mohammad | C10: 2 | E10: 5 | F10: Large size
A11: Rasul | B11: Hamid | C11: 2 | E11: 8 | F11: Very large size
E12: 13 | F12: Too large (size)
A14: How to play planning poker
A16: 1. Everyone type their number into their value field, don't hit return yet
A17: 2. Someone, perhaps a product owner, count down 3.. 2.. 1..
A18: 3. Then, everyone hit return to submit their value
